<?xml version="1.0" ?>
<robot name="Oskar III">

  <link name="base_link">
    <visual>
      <geometry>
        <box size="0.600 0.600 0.300"/>
      </geometry>
      <material name="gray">
        <color rgba=".66 .66 .67 .71" />
      </material>
    </visual>
  </link>

  <link name="left_wheel">
    <visual>
      <geometry>
        <cylinder radius="0.075" length="0.045"/>
      </geometry>
        <material name="black">
        <color rgba="0 0 0 1" />
      </material>
    </visual>
  </link>

  <link name="right_wheel">
    <visual>
      <geometry>
        <cylinder radius="0.075" length="0.045"/>
      </geometry>
      <material name="black">
        <color rgba="0 0 0 1" />
      </material>
    </visual>
  </link>

  <link name="body_mountpoint">
    <visual>
      <geometry>
        <box size="0.01 0.01 0.01"/> 
      </geometry>
    </visual>
  </link>

    <link name="body_mountpoint2">
    <visual>
      <geometry>
        <box size="0.01 0.01 0.01"/> 
      </geometry>
    </visual>
  </link>

  <link name="body">
    <visual>
      <geometry>
        <cylinder radius="0.250" length="0.560"/>
      </geometry> 
      <material name="gray">
        <color rgba=".66 .66 .67 1" />
      </material>
    </visual>
  </link>

  <link name="left_shoulder">
    <visual>
      <geometry>
        <box size="0.01 0.01 0.01"/>
      </geometry>
       <material name="gray">
        <color rgba=".66 .66 .67 1" />
      </material>
    </visual>
  </link>


  <link name="left_upper_arm_rotational">
    <visual>
      <geometry>
        <box size="0.01 0.01 0.01"/>
      </geometry>
       <material name="gray">
        <color rgba=".66 .66 .67 1" />
      </material>
    </visual>
  </link>


  <link name="left_upper_arm">
    <visual>
      <geometry>
        <cylinder radius="0.01685" length=".330"/>
      </geometry>
       <material name="gray">
        <color rgba=".66 .66 .67 1" />
      </material>
    </visual>
  </link>


  <link name="right_shoulder">
    <visual>
      <geometry>
        <box size="0.01 0.01 0.01"/>
      </geometry>
       <material name="gray">
        <color rgba=".66 .66 .67 1" />
      </material>
    </visual>
  </link>


  <link name="right_upper_arm_rotational">
    <visual>
      <geometry>
        <box size="0.01 0.01 0.01"/>
      </geometry>
       <material name="gray">
        <color rgba=".66 .66 .67 1" />
      </material>
    </visual>
  </link>


  <link name="right_upper_arm">
    <visual>
      <geometry>
        <cylinder radius="0.01685" length=".330"/>
      </geometry>
       <material name="gray">
        <color rgba=".66 .66 .67 1" />
      </material>
    </visual>
  </link>


  <link name="left_forearm">
    <visual>
      <geometry>
        <cylinder radius="0.01685" length=".330"/>
      </geometry>
 <material name="gray">
        <color rgba=".66 .66 .67 .71" />
      </material>
    </visual>
  </link>

  <link name="right_forearm">
    <visual>
      <geometry>
        <cylinder radius="0.01685" length=".330"/>
      </geometry>
 <material name="gray">
        <color rgba=".66 .66 .67 .71" />
      </material>
    </visual>
  </link>

  <link name="left_elbow">
    <visual>
      <geometry>
        <box size="0.01 0.01 0.01"/>
      </geometry>
       <material name="gray">
        <color rgba=".66 .66 .67 1" />
      </material>
    </visual>
  </link>

  <link name="right_elbow">
    <visual>
      <geometry>
        <box size="0.01 0.01 0.01"/>
      </geometry>
       <material name="gray">
        <color rgba=".66 .66 .67 1" />
      </material>
    </visual>
  </link>


  <link name="right_gripper">
     <visual>
      <geometry>
        <box size="0.1 0.1 0.1"/>
      </geometry>
       <material name="gray">
        <color rgba=".66 .66 .67 1" />
      </material>
    </visual>
  </link>

  <joint name="right_ripper_to_right_forearm" type="fixed">
    <parent link="right_forearm"/>
    <child link="right_gripper"/>
    <origin xyz="0.0 0.0 -0.165" rpy="0.0 0.0 0.0"/>
    
  </joint>


  <link name="left_gripper">
     <visual>
      <geometry>
        <box size="0.1 0.1 0.1"/>
      </geometry>
       <material name="gray">
        <color rgba=".66 .66 .67 1" />
      </material>
    </visual>
  </link>

  <joint name="left_ripper_to_right_forearm" type="fixed">
    <parent link="left_forearm"/>
    <child link="left_gripper"/>
    <origin xyz="0.0 0.0 -0.165" rpy="0.0 0.0 0.0"/>
    
  </joint>


  <joint name="body_to_mount" type="fixed">
    <parent link="body_mountpoint2"/>
    <child link="body"/>
    <origin xyz="0.0 0.0 0.080" rpy="0.0 0.0 0.0"/>
  </joint>


  <joint name="left_wheel_to_base" type="continuous">
    <parent link="base_link"/>
    <child link="right_wheel"/>
    <origin xyz="0.214 -0.240 -0.110" rpy="1.57 0.0 0.0"/>
    <axis xyz="0 0 1"/>
  </joint>

  <joint name="right_wheel_to_base" type="continuous">
    <parent link="base_link"/>
    <child link="left_wheel"/>
    <origin xyz="0.214 0.240 -0.110" rpy="1.57 0.0 0.0"/>
    <axis xyz="0 0 1"/>
  </joint>

  <joint name="kneeling_joint" type="prismatic">
    <limit lower="0.620" upper="0.950" effort="0.0" velocity="0.0"/>
    <origin xyz="0 0 0.0860"/>
    <axis xyz="0.0 0.0 1.0"/>
    <parent link="base_link"/>
    <child link="body_mountpoint"/>
  </joint>

  <joint name="bowing_joint" type="revolute">
    <parent link="body_mountpoint"/>
    <child link="body_mountpoint2"/>
    <origin xyz="0.0 0.0 0.0" rpy="0.0 0.0 0.0"/>
    <axis xyz="0 1 0"/>
    <limit lower="0" upper="0.4" effort="0.0" velocity="0.0"/> 
  </joint>

  <joint name="left_shoulder_to_body" type="revolute">
    <limit upper="0" lower="-3.14" effort="0.0" velocity="0.0"/>
    <origin xyz="0 0.317 0.213" rpy="0.0 0.0 0.0"/>
    <axis xyz="0.0 1 0.0"/>
    <parent link="body"/>
    <child link="left_shoulder"/>
  </joint>

  <joint name="left_upper_arm_to_left_shoulder" type="revolute">
    <limit lower="0.0" upper="3.14" effort="0.0" velocity="0.0"/>
    <origin xyz="0.0 0.0 0" rpy="0.0 0.0 0.0"/>
    <axis xyz="1.0 0.0 0.0"/>
    <parent link="left_shoulder"/>
    <child link="left_upper_arm_rotational"/>
  </joint>

  <joint name="left_upper_arm_to_shoulder_joints" type="fixed">
    <parent link="left_upper_arm_rotational"/>
    <child link="left_upper_arm"/>
    <origin xyz="0.0 0.0 -0.165" rpy="0.0 0.0 0.0"/>
  </joint>


   <joint name="right_shoulder_to_body" type="revolute">
    <limit lower="-3.14" upper="0" effort="0.0" velocity="0.0"/>
    <origin xyz="0 -0.317 0.213" rpy="0.0 0 0.0"/>
    <axis xyz="0.0 1 0.0"/>
    <parent link="body"/>
    <child link="right_shoulder"/>
  </joint>

  <joint name="right_upper_arm_to_right_shoulder" type="revolute">
    <limit lower="0.0" upper="3.14" effort="0.0" velocity="0.0"/>
    <origin xyz="0.0 0.0 0" rpy="0.0 0.0 0.0"/>
    <axis xyz="-1.0 0.0 0.0"/>
    <parent link="right_shoulder"/>
    <child link="right_upper_arm_rotational"/>
  </joint>

  <joint name="right_upper_arm_to_shoulder_joints" type="fixed">
    <parent link="right_upper_arm_rotational"/>
    <child link="right_upper_arm"/>
    <origin xyz="0.0 0.0 -0.165" rpy="0.0 0.0 0.0"/>
  </joint>


  <joint name="right_elbow_joint" type="revolute">
    <parent link="right_upper_arm"/>
    <child link="right_elbow"/>
    <origin xyz="0.0 0.0 -0.165" rpy="0.0 0.0 0.0"/>
    <limit lower="0.0" upper="2.04" effort="0.0" velocity="0.0"/>
      <axis xyz="0.0 -1.0 0.0"/>

  </joint>

    <joint name="left_elbow_joint" type="revolute">
    <parent link="left_upper_arm"/>
    <child link="left_elbow"/>
    <axis xyz="0 -1.0 0.0"/>
    <origin xyz="0.0 0.0 -0.165 " rpy="0.0 0.0 0.0"/>
    <limit lower="0.0" upper="2.04" effort="0.0" velocity="0.0"/>
    
  </joint>


  <joint name="left_forearm_to_elbow" type="fixed">
    <parent link="left_elbow"/>
    <child link="left_forearm"/>
    <origin xyz="0.0 0.0 -0.165" rpy="0.0 0.0 0.0"/>
    
  </joint>

  <joint name="right_forearm_to_elbow" type="fixed">
    <parent link="right_elbow"/>
    <child link="right_forearm"/>
    <origin xyz="0.0 0.0 -0.165" rpy="0.0 0.0 0.0"/>
    
  </joint>

</robot>
